<?xml version="1.0" encoding="utf-8"?>
<!-- This URDF was automatically created by SolidWorks to URDF Exporter! Originally created by Stephen Brawner (brawner@gmail.com) 
     Commit Version: 1.6.0-4-g7f85cfe  Build Version: 1.6.7995.38578
     For more information, please see http://wiki.ros.org/sw_urdf_exporter -->
<robot
  name="scara">
  <link name="world"/>
  <joint name="fixed_base_joint" type="fixed">
    <parent link="world"/>
    <child link="base_link"/>
    <origin xyz="0 0 0" rpy="0 0 0"/>
  </joint>
  <link
    name="base_link">
    <inertial>
      <origin
        xyz="-0.03072504059151 3.69818661612541E-06 0.0586776821859028"
        rpy="0 0 0" />
      <mass
        value="0.685155677338949" />
      <inertia
        ixx="0.000569132873620359"
        ixy="1.81194969892652E-10"
        ixz="-1.37702714471506E-13"
        iyy="0.00101245342653283"
        iyz="-2.30452420636814E-09"
        izz="0.00116816330446868" />
    </inertial>
    <visual>
      <origin
        xyz="0 0 0"
        rpy="0 0 0" />
      <geometry>
        <mesh
          filename="package://scara_description/meshes/base_link.STL" />
      </geometry>
      <material
        name="">
        <color
          rgba="0.752941176470588 0.752941176470588 0.752941176470588 1" />
      </material>
    </visual>
    <collision>
      <origin
        xyz="0 0 0"
        rpy="0 0 0" />
      <geometry>
        <mesh
          filename="package://scara_description/meshes/base_link.STL" />
      </geometry>
    </collision>
  </link>
  <link
    name="hand1">
    <inertial>
      <origin
        xyz="0.125000000000105 -1.03746801586298E-12 0.021"
        rpy="0 0 0" />
      <mass
        value="0.312571440630505" />
      <inertia
        ixx="0.000207885325071692"
        ixy="7.74767417835879E-15"
        ixz="3.0751638530257E-21"
        iyy="0.00202288021926723"
        iyz="-1.20399541685312E-22"
        izz="0.00221357127106959" />
    </inertial>
    <visual>
      <origin
        xyz="0 0 0"
        rpy="0 0 0" />
      <geometry>
        <mesh
          filename="package://scara_description/meshes/hand1.STL" />
      </geometry>
      <material
        name="">
        <color
          rgba="0.564705882352941 0.564705882352941 0.564705882352941 1" />
      </material>
    </visual>
    <collision>
      <origin
        xyz="0 0 0"
        rpy="0 0 0" />
      <geometry>
        <mesh
          filename="package://scara_description/meshes/hand1.STL" />
      </geometry>
    </collision>
  </link>
  <joint
    name="hand1_joint"
    type="revolute">
    <origin
      xyz="0 0 0.115"
      rpy="0 0 0" />
    <parent
      link="base_link" />
    <child
      link="hand1" />
    <axis
      xyz="0 0 -1" />
    <dynamics damping="0.05" friction="0.0"/>
    <limit effort="1000.0" velocity="4.2" lower="-3.14" upper="3.14"/>
  </joint>
  <link
    name="hand2">
    <inertial>
      <origin
        xyz="0.0404298544009521 5.72616428484963E-06 0.0404009855273928"
        rpy="0 0 0" />
      <mass
        value="0.442500998461731" />
      <inertia
        ixx="0.000202135419531902"
        ixy="-1.81190404914352E-10"
        ixz="-1.37702606015348E-13"
        iyy="0.000740634680509903"
        iyz="2.30452420637258E-09"
        izz="0.000892125400987182" />
    </inertial>
    <visual>
      <origin
        xyz="0 0 0"
        rpy="0 0 0" />
      <geometry>
        <mesh
          filename="package://scara_description/meshes/hand2.STL" />
      </geometry>
      <material
        name="">
        <color
          rgba="0.752941176470588 0.752941176470588 0.752941176470588 1" />
      </material>
    </visual>
    <collision>
      <origin
        xyz="0 0 0"
        rpy="0 0 0" />
      <geometry>
        <mesh
          filename="package://scara_description/meshes/hand2.STL" />
      </geometry>
    </collision>
  </link>
  <joint
    name="hand2_joint"
    type="revolute">
    <origin
      xyz="0.250000000000206 0 0.039"
      rpy="0 0 0" />
    <parent
      link="hand1" />
    <child
      link="hand2" />
    <axis
      xyz="0 0 -1" />
    <dynamics damping="0.05" friction="0.0"/>
    <limit effort="1000.0" velocity="4.2" lower="-3.14" upper="3.14"/>
  </joint>
  <link
    name="hand3">
    <inertial>
      <origin
        xyz="1.68896665477258E-05 4.27009763541216E-06 0.0418868919689874"
        rpy="0 0 0" />
      <mass
        value="0.174475673560537" />
      <inertia
        ixx="0.000109915128727093"
        ixy="3.73632524589427E-09"
        ixz="-2.3045251964297E-09"
        iyy="5.65000184883731E-05"
        iyz="1.34068709466748E-13"
        izz="9.55331504251612E-05" />
    </inertial>
    <visual>
      <origin
        xyz="0 0 0"
        rpy="0 0 0" />
      <geometry>
        <mesh
          filename="package://scara_description/meshes/hand3.STL" />
      </geometry>
      <material
        name="">
        <color
          rgba="0.564705882352941 0.564705882352941 0.564705882352941 1" />
      </material>
    </visual>
    <collision>
      <origin
        xyz="0 0 0"
        rpy="0 0 0" />
      <geometry>
        <mesh
          filename="package://scara_description/meshes/hand3.STL" />
      </geometry>
    </collision>
  </link>
  <link name="tool0">
    <inertial>
      <mass value="0.001"/>
      <origin xyz="0 0 0" rpy="0 0 0"/>
      <inertia ixx="1e-6" ixy="0" ixz="0" iyy="1e-6" iyz="0" izz="1e-6"/>
    </inertial>
    <visual>
      <origin xyz="0 0 0.05" rpy="0 0 0"/>
      <geometry>
        <cylinder length="0.1" radius="0.01"/>
      </geometry>
      <material name="tool_color">
        <color rgba="0.8 0.8 0.0 1.0"/>
      </material>
    </visual>
    <collision>
      <origin xyz="0 0 0.05" rpy="0 0 0"/>
      <geometry>
        <cylinder length="0.1" radius="0.01"/>
      </geometry>
    </collision>
  </link>
  
  <joint name="tool0_fixed_joint" type="fixed">
    <parent link="hand3"/>
    <child link="tool0"/>
    <!-- смещение TCP относительно hand3, подбери, как удобно -->
    <origin xyz="0 0 0.0" rpy="0 0 0"/>
  </joint>
  
  <joint
    name="hand3_joint"
    type="prismatic">
    <origin
      xyz="0.241500000000205 0 0.001"
      rpy="0 0 0" />
    <parent
      link="hand2" />
    <child
      link="hand3" />
    <axis
      xyz="0 0 -1" />
    <dynamics damping="20.0" friction="0.0"/>
    <limit effort="1000.0" velocity="0.63" lower="0.0" upper="0.1"/>
  </joint>
    <ros2_control name="GazeboSimSystem" type="system">
    <hardware>
      <plugin>gz_ros2_control/GazeboSimSystem</plugin>
      <param name="update_rate">100</param>

    </hardware>
	<joint name="hand1_joint">
        <command_interface name="position">
          <param name="min">-3.14</param>
          <param name="max">3.14</param>
        </command_interface>
        <state_interface name="position"/>
        <state_interface name="velocity"/>
    </joint>

    <joint name="hand2_joint">
        <command_interface name="position">
            <param name="min">-3.14</param>
            <param name="max">3.14</param>
        </command_interface>
        <state_interface name="position"/>
        <state_interface name="velocity"/>
    </joint>

    <joint name="hand3_joint">
        <command_interface name="position">
            <param name="min">0.0</param>
            <param name="max">0.1</param>
        </command_interface>
        <state_interface name="position"/>
        <state_interface name="velocity"/>
    </joint>
  </ros2_control>
  <gazebo>
    <plugin filename="libgz_ros2_control-system.so"
            name="gz_ros2_control::GazeboSimROS2ControlPlugin">
      <robot_param>robot_description</robot_param>
      <robot_param_node>robot_state_publisher</robot_param_node>
      <parameters>$(find scara_control)/config/controllers.yaml</parameters>
      <controller_manager_name>controller_manager</controller_manager_name>
    </plugin>
  </gazebo>
</robot>


